2021-10-17 21:10:37.559896 :: Traceback (most recent call last):
  File "C:\Users\tobia\AppData\Local\Programs\Python\Python39\lib\site-packages\imageai\Prediction\__init__.py", line 246, in predictImage
    image_to_predict = image.load_img(image_input, target_size=(self.__input_image_size, self.__input_image_size))
  File "C:\Users\tobia\AppData\Local\Programs\Python\Python39\lib\site-packages\tensorflow\python\keras\preprocessing\image.py", line 313, in load_img
    return image.load_img(path, grayscale=grayscale, color_mode=color_mode,
  File "C:\Users\tobia\AppData\Local\Programs\Python\Python39\lib\site-packages\keras_preprocessing\image\utils.py", line 114, in load_img
    img = pil_image.open(io.BytesIO(f.read()))
  File "C:\Users\tobia\AppData\Local\Programs\Python\Python39\lib\site-packages\PIL\Image.py", line 3030, in open
    raise UnidentifiedImageError(
PIL.UnidentifiedImageError: cannot identify image file <_io.BytesIO object at 0x000002C709D1A9A0>

During handling of the above exception, another exception occurred:

Traceback (most recent call last):
  File "C:\Users\tobia\Desktop\WhatsDisPic\main.py", line 50, in <module>
    runAI(name, root, base)
  File "C:\Users\tobia\Desktop\WhatsDisPic\ai.py", line 18, in runAI
    predictions, probabilities = prediction.predictImage(
  File "C:\Users\tobia\AppData\Local\Programs\Python\Python39\lib\site-packages\imageai\Prediction\__init__.py", line 252, in predictImage
    raise ValueError("You have set a path to an invalid image file.")
ValueError: You have set a path to an invalid image file.


2021-10-17 21:35:23.971424 :: Traceback (most recent call last):
  File "C:\Users\tobia\Desktop\WhatsDisPic\main.py", line 37, in <module>
    input(base)
NameError: name 'base' is not defined


2021-10-18 17:49:19.897016 :: Traceback (most recent call last):
  File "c:\Users\tobia\Desktop\WhatsDisPic\main.py", line 52, in <module>
    runDominant(name, root, base, ext)
  File "c:\Users\tobia\Desktop\WhatsDisPic\dominant.py", line 25, in runDominant
    Image.new("RGB", (Image.open(f"{root}/{name}").size()), (dominantColor)).save(
TypeError: 'tuple' object is not callable


2021-10-18 17:49:19.901018 :: Traceback (most recent call last):
  File "c:\Users\tobia\Desktop\WhatsDisPic\main.py", line 52, in <module>
    runDominant(name, root, base, ext)
  File "c:\Users\tobia\Desktop\WhatsDisPic\dominant.py", line 25, in runDominant
    Image.new("RGB", (Image.open(f"{root}/{name}").size()), (dominantColor)).save(
TypeError: 'tuple' object is not callable

During handling of the above exception, another exception occurred:

Traceback (most recent call last):
  File "C:\Users\tobia\AppData\Local\Programs\Python\Python39\lib\shutil.py", line 814, in move
    os.rename(src, real_dst)
FileNotFoundError: [WinError 2] Det g�r inte att hitta filen: './images/toDo\\Namnl�s/dominantColor.png' -> './images/toDo\\Namnl�s/dominantColor.png-failed.png'

During handling of the above exception, another exception occurred:

Traceback (most recent call last):
  File "c:\Users\tobia\Desktop\WhatsDisPic\main.py", line 63, in <module>
    moveOriginal(name, root, base, ext, True)
  File "c:\Users\tobia\Desktop\WhatsDisPic\moveOriginal.py", line 22, in moveOriginal
    move(f"{root}/{name}", (f"{root}/{name}-failed{ext}"))
  File "C:\Users\tobia\AppData\Local\Programs\Python\Python39\lib\shutil.py", line 834, in move
    copy_function(src, real_dst)
  File "C:\Users\tobia\AppData\Local\Programs\Python\Python39\lib\shutil.py", line 443, in copy2
    copyfile(src, dst, follow_symlinks=follow_symlinks)
  File "C:\Users\tobia\AppData\Local\Programs\Python\Python39\lib\shutil.py", line 265, in copyfile
    with open(src, 'rb') as fsrc, open(dst, 'wb') as fdst:
FileNotFoundError: [Errno 2] No such file or directory: './images/toDo\\Namnl�s/dominantColor.png'


2021-10-18 17:49:21.496483 :: Traceback (most recent call last):
  File "c:\Users\tobia\Desktop\WhatsDisPic\main.py", line 52, in <module>
    runDominant(name, root, base, ext)
  File "c:\Users\tobia\Desktop\WhatsDisPic\dominant.py", line 25, in runDominant
    Image.new("RGB", (Image.open(f"{root}/{name}").size()), (dominantColor)).save(
TypeError: 'tuple' object is not callable


2021-10-18 17:49:21.496483 :: Traceback (most recent call last):
  File "c:\Users\tobia\Desktop\WhatsDisPic\main.py", line 52, in <module>
    runDominant(name, root, base, ext)
  File "c:\Users\tobia\Desktop\WhatsDisPic\dominant.py", line 25, in runDominant
    Image.new("RGB", (Image.open(f"{root}/{name}").size()), (dominantColor)).save(
TypeError: 'tuple' object is not callable

During handling of the above exception, another exception occurred:

Traceback (most recent call last):
  File "C:\Users\tobia\AppData\Local\Programs\Python\Python39\lib\shutil.py", line 814, in move
    os.rename(src, real_dst)
FileNotFoundError: [WinError 2] Det g�r inte att hitta filen: './images/toDo\\Namnl�s/original.png' -> './images/toDo\\Namnl�s/original.png-failed.png'

During handling of the above exception, another exception occurred:

Traceback (most recent call last):
  File "c:\Users\tobia\Desktop\WhatsDisPic\main.py", line 63, in <module>
    moveOriginal(name, root, base, ext, True)
  File "c:\Users\tobia\Desktop\WhatsDisPic\moveOriginal.py", line 22, in moveOriginal
    move(f"{root}/{name}", (f"{root}/{name}-failed{ext}"))
  File "C:\Users\tobia\AppData\Local\Programs\Python\Python39\lib\shutil.py", line 834, in move
    copy_function(src, real_dst)
  File "C:\Users\tobia\AppData\Local\Programs\Python\Python39\lib\shutil.py", line 443, in copy2
    copyfile(src, dst, follow_symlinks=follow_symlinks)
  File "C:\Users\tobia\AppData\Local\Programs\Python\Python39\lib\shutil.py", line 265, in copyfile
    with open(src, 'rb') as fsrc, open(dst, 'wb') as fdst:
FileNotFoundError: [Errno 2] No such file or directory: './images/toDo\\Namnl�s/original.png'


2021-10-18 17:53:00.219006 :: Traceback (most recent call last):
  File "C:\Users\tobia\Desktop\WhatsDisPic\main.py", line 52, in <module>
    runDominant(name, root, base, ext)
  File "C:\Users\tobia\Desktop\WhatsDisPic\dominant.py", line 25, in runDominant
    Image.new("RGB", (Image.open(f"{root}/{name}").size()), (dominantColor)).save(
TypeError: 'tuple' object is not callable


2021-10-18 17:53:00.224007 :: Traceback (most recent call last):
  File "C:\Users\tobia\Desktop\WhatsDisPic\main.py", line 52, in <module>
    runDominant(name, root, base, ext)
  File "C:\Users\tobia\Desktop\WhatsDisPic\dominant.py", line 25, in runDominant
    Image.new("RGB", (Image.open(f"{root}/{name}").size()), (dominantColor)).save(
TypeError: 'tuple' object is not callable

During handling of the above exception, another exception occurred:

Traceback (most recent call last):
  File "C:\Users\tobia\AppData\Local\Programs\Python\Python39\lib\shutil.py", line 814, in move
    os.rename(src, real_dst)
FileNotFoundError: [WinError 2] Det g�r inte att hitta filen: './images/toDo/original.png' -> './images/toDo/original.png-failed.png'

During handling of the above exception, another exception occurred:

Traceback (most recent call last):
  File "C:\Users\tobia\Desktop\WhatsDisPic\main.py", line 63, in <module>
    moveOriginal(name, root, base, ext, True)
  File "C:\Users\tobia\Desktop\WhatsDisPic\moveOriginal.py", line 22, in moveOriginal
    move(f"{root}/{name}", (f"{root}/{name}-failed{ext}"))
  File "C:\Users\tobia\AppData\Local\Programs\Python\Python39\lib\shutil.py", line 834, in move
    copy_function(src, real_dst)
  File "C:\Users\tobia\AppData\Local\Programs\Python\Python39\lib\shutil.py", line 443, in copy2
    copyfile(src, dst, follow_symlinks=follow_symlinks)
  File "C:\Users\tobia\AppData\Local\Programs\Python\Python39\lib\shutil.py", line 265, in copyfile
    with open(src, 'rb') as fsrc, open(dst, 'wb') as fdst:
FileNotFoundError: [Errno 2] No such file or directory: './images/toDo/original.png'


2021-10-18 17:54:09.382001 :: Traceback (most recent call last):
  File "C:\Users\tobia\Desktop\WhatsDisPic\main.py", line 52, in <module>
    runDominant(name, root, base, ext)
  File "C:\Users\tobia\Desktop\WhatsDisPic\dominant.py", line 25, in runDominant
    Image.new("RGB", (Image.open(f"{root}/{name}").size()), (dominantColor)).save(
TypeError: 'tuple' object is not callable


2021-10-18 17:55:45.437494 :: Traceback (most recent call last):
  File "c:\Users\tobia\Desktop\WhatsDisPic\main.py", line 52, in <module>
    runDominant(name, root, base, ext)
  File "c:\Users\tobia\Desktop\WhatsDisPic\dominant.py", line 25, in runDominant
    Image.new("RGB", (Image.open(f"{root}/{name}").size()), (dominantColor)).save(
TypeError: 'tuple' object is not callable


2021-10-18 17:55:45.442495 :: Traceback (most recent call last):
  File "c:\Users\tobia\Desktop\WhatsDisPic\main.py", line 52, in <module>
    runDominant(name, root, base, ext)
  File "c:\Users\tobia\Desktop\WhatsDisPic\dominant.py", line 25, in runDominant
    Image.new("RGB", (Image.open(f"{root}/{name}").size()), (dominantColor)).save(
TypeError: 'tuple' object is not callable

During handling of the above exception, another exception occurred:

Traceback (most recent call last):
  File "C:\Users\tobia\AppData\Local\Programs\Python\Python39\lib\shutil.py", line 814, in move
    os.rename(src, real_dst)
FileNotFoundError: [WinError 3] Det g�r inte att hitta s�kv�gen: './images/toDo/original.png' -> './images/toDo/failed/original.png-failed.png'

During handling of the above exception, another exception occurred:

Traceback (most recent call last):
  File "c:\Users\tobia\Desktop\WhatsDisPic\main.py", line 63, in <module>
    moveOriginal(name, root, base, ext, True)
  File "c:\Users\tobia\Desktop\WhatsDisPic\moveOriginal.py", line 20, in moveOriginal
    move(f"{root}/{name}", (f"{root}/failed/{name}-failed{ext}"))
  File "C:\Users\tobia\AppData\Local\Programs\Python\Python39\lib\shutil.py", line 834, in move
    copy_function(src, real_dst)
  File "C:\Users\tobia\AppData\Local\Programs\Python\Python39\lib\shutil.py", line 443, in copy2
    copyfile(src, dst, follow_symlinks=follow_symlinks)
  File "C:\Users\tobia\AppData\Local\Programs\Python\Python39\lib\shutil.py", line 265, in copyfile
    with open(src, 'rb') as fsrc, open(dst, 'wb') as fdst:
FileNotFoundError: [Errno 2] No such file or directory: './images/toDo/failed/original.png-failed.png'


2021-10-18 18:00:09.147049 :: Traceback (most recent call last):
  File "c:\Users\tobia\Desktop\WhatsDisPic\main.py", line 52, in <module>
    runDominant(name, root, base, ext)
  File "c:\Users\tobia\Desktop\WhatsDisPic\dominant.py", line 25, in runDominant
    Image.new("RGB", (Image.open(f"{root}/{name}").size()), (dominantColor)).save(
TypeError: 'tuple' object is not callable


2021-10-18 18:01:02.080627 :: Traceback (most recent call last):
  File "c:\Users\tobia\Desktop\WhatsDisPic\main.py", line 52, in <module>
    runDominant(name, root, base, ext)
  File "c:\Users\tobia\Desktop\WhatsDisPic\dominant.py", line 25, in runDominant
    width, height = Image.open(f"{root}/{name}").size()
TypeError: 'tuple' object is not callable


2021-10-18 18:02:17.841119 :: Traceback (most recent call last):
  File "c:\Users\tobia\Desktop\WhatsDisPic\main.py", line 52, in <module>
    runDominant(name, root, base, ext)
  File "c:\Users\tobia\Desktop\WhatsDisPic\dominant.py", line 27, in runDominant
    Image.new("RGB", width, height(), (dominantColor)).save(
TypeError: 'int' object is not callable


2021-10-18 18:02:46.492752 :: Traceback (most recent call last):
  File "c:\Users\tobia\Desktop\WhatsDisPic\main.py", line 52, in <module>
    runDominant(name, root, base, ext)
  File "c:\Users\tobia\Desktop\WhatsDisPic\dominant.py", line 27, in runDominant
    Image.new("RGB", width, height, (dominantColor)).save(
TypeError: new() takes from 2 to 3 positional arguments but 4 were given


